Workbook

Sheet COVER
B2: GOTO (GOTO.JK) — FINANCIAL ANALYSIS MODEL
B3: PT GoTo Gojek Tokopedia Tbk | FY2024–FY2025 Actuals
B6: Sheet Index | C6: Description | D6: Status
B7: COVER | C7: Model index & color guide | D7: ✓
B8: ASSUMPTIONS | C8: Key drivers, growth rates & margin inputs | D8: → Fill
B9: IS | C9: Income Statement — FY2024 & FY2025 actuals | D9: → Fill
B10: BS | C10: Balance Sheet — FY2024 & FY2025 actuals | D10: → Fill
B11: CF | C11: Cash Flow Statement — FY2024 & FY2025 | D11: → Fill
B12: RATIOS | C12: Profitability, liquidity & efficiency ratios | D12: → formula
B13: SEGMENT | C13: Revenue & GTV breakdown by business unit | D13: → Fill
B14: KPI | C14: Tech-specific KPIs (GTV, take rate, EBITDA) | D14: → formula
B17: Color Coding Convention
B18: Blue text | C18: Hardcoded input — numbers you type from LK
B19: Green text | C19: Formula linking from another sheet in this workbook
B20: Red text | C20: External link (e.g., Bloomberg, consensus estimates)
B21: Black text | C21: Formula calculated within this sheet
B22: Yellow bg | C22: Key assumption — review before use
B24: Units: All financial figures in IDR Millions (Rp Juta) unless stated.
B25: Source: PT GoTo Gojek Tokopedia Tbk — Laporan Keuangan Konsolidasian 31 Desember 2025.

Sheet FLAGS
A1: GOTO (GOTO.JK) — Consolidated Balance Sheet (Statement of Financial Position)
A2: As of 31 December | Rp Juta (IDR Millions)
A3: No | B3: Amount/Cell Ref | C3: Flags | D3: Severity | E3: Status | F3: Insights
A4: Follow-Ups
A5: 1 | B5: =SEGMENT!E7 -> 3780801 | C5: Lending revenue +95% YoY | D5: High | E5: Resolve | F5: Lending receivables increased to IDR 3.1T, driving 95.4% YoY growth. Overall coverage ratio remained at 13.0%, while >30-day overdue receivables were covered at 89.0%, indicating conservative provisioning despite rapid portfolio expansion. The overdue ratio increased from 7.8% to 10.2%, which remains manageable but should be monitored as lending scales.
A6: 2 | B6: =IS!D22 -> -78767510 | C6: FY2023 non-recurring goodwill impairment (IDR 78.7B) | D6: High | E6: Resolve | F6: FY2023 earnings were significantly affected by a non-recurring goodwill impairment related to TOKO. The write-down reflected revised valuation assumptions following the tech sector downturn and changes in competitive outlook. This item is non-operating and should not affect normalized earnings analysis.
A7: 3 | B7: =IS!E25 -> -2305125 | C7: One-off equity method loss from associates | D7: High | E7: Resolve | F7: The equity-method loss primarily reflects GoTo's 24.9% ownership in TOKO following deconsolidation. The reported loss represents GoTo's proportional share of TOKO's FY2024 net loss and is considered a one-off accounting impact rather than deterioration in GoTo's core operations.
A8: 4 | B8: =BS!F7 -> 304955 | C8: Time deposits declined 82.6% | D8: Medium | E8: Resolve | F8: Time deposits decreased by 82.6% by FY2025 despite a strong cash balance of IDR 21.7T. The movement appears consistent with treasury optimization rather than liquidity constraints.
A9: 5 | B9: =BS!F8 -> 1000000 | C9: Restricted cash recognized | D9: Low | E9: Resolve | F9: Restricted cash was recognized beginning in FY2024 following a secured credit facility with Bank Mandiri. The balance represents pledged cash collateral and does not indicate operational cash usage.
A10: 6 | B10: =BS!D25 -> 8036379 | C10: Intangible assets down 82% after deconsolidation | D10: Low | E10: Resolve | F10: The decline was primarily driven by the deconsolidation of TOKO, resulting in derecognition of related intangible assets. This reflects a change in consolidation scope rather than asset impairment.
A11: 7 | B11: =BS!F27 -> 10594799 | C11: Increase in investment in associates after deconsolidation | D11: High | E11: Resolve | F11: The increase reflects the reclassification of GoTo's remaining investment in TOKO following deconsolidation. The accounting treatment is consistent with PSAK 228 and does not represent a new capital investment.

Sheet ASSUMPTIONS
B1: GOTO — Key Assumptions & Drivers
B2: Assumption / Driver | C2: FY2023A | D2: FY2024A | E2: Growth 23-24 | F2: % Growth 23-24 | G2: FY2025A | H2: Growth 24-25 | I2: % Growth 24-25 | J2: Trend | K2: FY2026F Bear | L2: FY2026F Base | M2: FY2026F Bull | O2: Scenario Assumptions | P2: Rationale
B3: A. REVENUE ASSUMPTIONS
B4: Net Revenue (Rp Juta) | C4: =IS!D4 -> 14785492 | D4: =IS!E4 -> 15894462 | E4: =D4-C4 -> 1108970 | F4: =IF(C4=0, "n.a",E4/C4) -> 0.07500393 | G4: =IS!F4 -> 18322117 | H4: =G4-D4 -> 2427655 | I4: =IF(D4=0, "n.a", H4/D4) -> 0.1527359
B5: Delivery Services Revenue | C5: =SEGMENT!C5 -> 2131131 | D5: =SEGMENT!D5 -> 5344984 | E5: =D5-C5 -> 3213853 | F5: =IF(C5=0, "n.a",E5/C5) -> 1.5080504 | G5: =SEGMENT!E5 -> 5779206 | H5: =G5-D5 -> 434222 | I5: =IF(D5=0, "n.a", H5/D5) -> 0.081239158 | J5: =IF(OR(D5="", G5=""), "", IF(AND(D5<0, G5<0, G5>D5), "Accelerating", IF(AND(D5<0, G5<0, G5<D5), "Decelerating", IF(AND(D5>=0, G5>=0, G5>D5), "Accelerating", IF(AND(D5>=0, G5>=0, G5<D5), "Decelerating", IF(ABS(G5-D5)<0.01, "Stable", "Structural Break")))))) -> Accelerating | K5: 0.05 | L5: 0.075 | M5: 0.09 | O5: Bear +5%: Order growth slows due to weaker consumer demand. Base +7.5%: Transaction volume grows broadly in line with FY2025 trends. Bull +9%: Higher order volume supported by merchant expansion and new strategic partnerships. | P5: Delivery Services is a relatively mature business with stable demand driven by the On-Demand ecosystem (primarily GoFood and GoSend). In the absence of major business catalysts, revenue growth is expected to normalize toward mid-single digits.
B6: Service Fee Revenue | C6: =SEGMENT!C6 -> 8665040 | D6: =SEGMENT!D6 -> 5801835 | E6: =D6-C6 -> -2863205 | F6: =IF(C6=0, "n.a",E6/C6) -> -0.33043183 | G6: =SEGMENT!E6 -> 5689230 | H6: =G6-D6 -> -112605 | I6: =IF(D6=0, "n.a", H6/D6) -> -0.019408515 | J6: Stabilizing/New Normal | K6: -0.03 | L6: -0.01 | M6: 0.01 | O6: Bear -3%: Recovery following the structural transition is slower than expected. Soft GMV growth and continued monetization pressure result in a modest decline in service fee revenue. Base -1%: The majority of the structural impact from the TikTok partnership has been absorbed in FY2025. FY2026 is expected to represent a stabilization period, with broadly stable GMV offset by a small residual impact on monetization. Bull +1%: The structural transition is fully absorbed, allowing modest revenue growth supported by stable GMV and incremental improvements in monetization efficiency. | P6: Service fee revenue primarily reflects platform take rates from merchants and driver partners. Following the TikTok partnership and changes in business structure, revenue is expected to stabilize with limited upside from structural monetization improvements.
B7: Lending Revenue | C7: =SEGMENT!C7 -> 409955 | D7: =SEGMENT!D7 -> 1935389 | E7: =D7-C7 -> 1525434 | F7: =IF(C7=0, "n.a",E7/C7) -> 3.7209791 | G7: =SEGMENT!E7 -> 3780801 | H7: =G7-D7 -> 1845412 | I7: =IF(D7=0, "n.a", H7/D7) -> 0.9535096 | J7: =IF(OR(D7="", G7=""), "", IF(AND(D7<0, G7<0, G7>D7), "Accelerating", IF(AND(D7<0, G7<0, G7<D7), "Decelerating", IF(AND(D7>=0, G7>=0, G7>D7), "Accelerating", IF(AND(D7>=0, G7>=0, G7<D7), "Decelerating", IF(ABS(G7-D7)<0.01, "Stable", "Structural Break")))))) -> Accelerating | K7: 0.35 | L7: 0.5 | M7: 0.75 | O7: Bear +35%: Loan growth moderates due to higher credit risk or tighter regulatory conditions. Base +50%: Strong loan book expansion continues while maintaining current asset quality. Bull +75%: Accelerated lending growth supported by continued portfolio expansion and stable credit performance. | P7: Although FY2025 recorded exceptional growth, the high base effect is expected to moderate year-over-year growth. Nevertheless, Lending remains GoTo's fastest-growing business segment, with future performance primarily dependent on disciplined credit risk management and NPL stability.
B8: E-commerce Service Fee Revenue | C8: =SEGMENT!C8 -> 0 | D8: =SEGMENT!D8 -> 621871 | E8: =D8-C8 -> 621871 | F8: =IF(C8=0, "n.a",E8/C8) -> n.a | G8: =SEGMENT!E8 -> 819724 | H8: =G8-D8 -> 197853 | I8: =IF(D8=0, "n.a", H8/D8) -> 0.31815762 | J8: =IF(OR(D8="", G8=""), "", IF(AND(D8<0, G8<0, G8>D8), "Accelerating", IF(AND(D8<0, G8<0, G8<D8), "Decelerating", IF(AND(D8>=0, G8>=0, G8>D8), "Accelerating", IF(AND(D8>=0, G8>=0, G8<D8), "Decelerating", IF(ABS(G8-D8)<0.01, "Stable", "Structural Break")))))) -> Accelerating | K8: 0.15 | L8: 0.22 | M8: 0.3 | O8: Bear +15%: Tokopedia GMV growth moderates more than expected. Base +22%: Positive GMV growth continues, albeit at a slower pace as the business matures. Bull +30%: Stronger GMV expansion and higher transaction volume support revenue growth. | P8: Revenue remains closely linked to Tokopedia's GMV performance. Following FY2025's high growth, normalization is expected as the platform reaches a more mature growth stage.
B9: Advertising Fee Revenue | C9: =SEGMENT!C9 -> 2195135 | D9: =SEGMENT!D9 -> 554997 | E9: =D9-C9 -> -1640138 | F9: =IF(C9=0, "n.a",E9/C9) -> -0.74716954 | G9: =SEGMENT!E9 -> 533268 | H9: =G9-D9 -> -21729 | I9: =IF(D9=0, "n.a", H9/D9) -> -0.039151563 | J9: Stabilizing/New Normal | K9: -0.05 | L9: 0 | M9: 0.05 | O9: Bear -5%: Lower advertiser spending reduces advertising revenue. Base 0%: Monetization remains broadly stable. Bull +5%: Higher advertiser activity and improved CPM support revenue growth. | P9: Advertising revenue is closely correlated with activity across the e-commerce and On-Demand ecosystems. Following Tokopedia's deconsolidation, advertising revenue is expected to remain broadly stable with limited structural growth.
B10: Others Revenue | C10: =SEGMENT!C10 -> 1384231 | D10: =SEGMENT!D10 -> 1635386 | E10: =D10-C10 -> 251155 | F10: =IF(C10=0, "n.a",E10/C10) -> 0.18144009 | G10: =SEGMENT!E10 -> 1719888 | H10: =G10-D10 -> 84502 | I10: =IF(D10=0, "n.a", H10/D10) -> 0.051670982 | J10: =IF(OR(D10="", G10=""), "", IF(AND(D10<0, G10<0, G10>D10), "Accelerating", IF(AND(D10<0, G10<0, G10<D10), "Decelerating", IF(AND(D10>=0, G10>=0, G10>D10), "Accelerating", IF(AND(D10>=0, G10>=0, G10<D10), "Decelerating", IF(ABS(G10-D10)<0.01, "Stable", "Structural Break")))))) -> Accelerating | K10: 0.02 | L10: 0.05 | M10: 0.07 | O10: Bear +2%: Growth reflects a cautious macroeconomic environment. Base +5%: Revenue continues to grow in line with the FY2024–FY2025 average growth rate of approximately 5%. Bull +7%: Incremental contribution from new revenue initiatives supports stronger growth. | P10: Other revenue is expected to grow at a moderate pace, broadly tracking the underlying growth of GoTo's core businesses while benefiting from selective new revenue initiatives.
B12: B. COST ASSUMPTIONS
B13: Assumption / Driver | C13: FY2023A | D13: FY2024A | E13: Growth 23-24 | F13: % Growth 23-24 | G13: FY2025A | H13: Growth 24-25 | I13: % Growth 24-25 | J13: Trend | K13: FY2026F Bear | L13: FY2026F Base | M13: FY2026F Bull | O13: Scenario Assumptions | P13: Rationale
B14: Costs and Expenses
B15: Cost of Revenues | C15: =IS!D7 -> -5093179 | D15: =IS!E7 -> -7413392 | E15: =D15-C15 -> -2320213 | F15: =IF(C15=0, "n.a",E15/C15) -> 0.45555301 | G15: =IS!F7 -> -7746034 | H15: =G15-D15 -> -332642 | I15: =IF(D15=0, "n.a", H15/D15) -> 0.044870418 | J15: =IF(OR(D15="", G15=""), "", IF(AND(D15<0, G15<0, G15>D15), "Decelerating", IF(AND(D15<0, G15<0, G15<D15), "Accelerating", IF(AND(D15>=0, G15>=0, G15>D15), "Decelerating", IF(AND(D15>=0, G15>=0, G15<D15), "Accelerating", IF(ABS(G15-D15)<0.01, "Stable", "Structural Break")))))) -> Accelerating | K15: 0.055 | L15: 0.05 | M15: 0.045 | O15: Bear +5.5%: Higher service volumes increase variable costs, partially offset by operating leverage. Base +5.0%: Cost growth remains below revenue growth, reflecting continued efficiency improvements. Bull +4.5%: Strong operating leverage and process optimization limit cost inflation despite higher transaction volumes. | P15: Cost of revenue is expected to increase primarily with transaction volume across the On-Demand and Financial Technology segments. Continued scale efficiencies and disciplined cost management are expected to keep cost growth below revenue growth, supporting further margin expansion.
B16: General & Administrative Expenses | C16: =IS!D8 -> -5647458 | D16: =IS!E8 -> -4396253 | E16: =D16-C16 -> 1251205 | F16: =IF(C16=0, "n.a",E16/C16) -> -0.22155189 | G16: =IS!F8 -> -3988925 | H16: =G16-D16 -> 407328 | I16: =IF(D16=0, "n.a", H16/D16) -> -0.092653448 | J16: =IF(OR(D16="", G16=""), "", IF(AND(D16<0, G16<0, G16>D16), "Decelerating", IF(AND(D16<0, G16<0, G16<D16), "Accelerating", IF(AND(D16>=0, G16>=0, G16>D16), "Decelerating", IF(AND(D16>=0, G16>=0, G16<D16), "Accelerating", IF(ABS(G16-D16)<0.01, "Stable", "Structural Break")))))) -> Decelerating | K16: 0.04 | L16: 0.02 | M16: 0.01 | O16: Bear +4.0%: Administrative costs normalize following prior restructuring, with inflationary pressure on corporate expenses. Base +2.0%: Ongoing cost discipline and limited headcount growth keep overhead increases modest. Bull +1.0%: Lean organizational structure and operating leverage largely offset inflationary pressures. | P16: Following significant cost rationalization over the past two years, G&A expenses are expected to remain well controlled. Future increases are primarily driven by inflation and normal corporate support requirements rather than organizational expansion.
B17: Sales & Marketing Expenses | C17: =IS!D9 -> -6430776 | D17: =IS!E9 -> -2849934 | E17: =D17-C17 -> 3580842 | F17: =IF(C17=0, "n.a",E17/C17) -> -0.55682891 | G17: =IS!F9 -> -3090124 | H17: =G17-D17 -> -240190 | I17: =IF(D17=0, "n.a", H17/D17) -> 0.084279145 | J17: =IF(OR(D17="", G17=""), "", IF(AND(D17<0, G17<0, G17>D17), "Decelerating", IF(AND(D17<0, G17<0, G17<D17), "Accelerating", IF(AND(D17>=0, G17>=0, G17>D17), "Decelerating", IF(AND(D17>=0, G17>=0, G17<D17), "Accelerating", IF(ABS(G17-D17)<0.01, "Stable", "Structural Break")))))) -> Accelerating | K17: 0.085 | L17: 0.09 | M17: 0.1 | O17: Bear +8.5%: Marketing investment remains disciplined, focusing on customer retention and efficient acquisition. Base +9.0%: Marketing spend increases to support sustainable revenue growth while maintaining acquisition efficiency. Bull +10.0%: Higher investment in targeted campaigns, particularly for the Lending segment and strategic growth initiatives. | P17: Marketing expenditure is expected to increase broadly in line with revenue growth as GoTo continues investing in customer acquisition and engagement. Incremental spending is expected to remain targeted toward higher-return growth segments, particularly Financial Technology.
B18: Product Development Expenses | C18: =IS!D10 -> -3517369 | D18: =IS!E10 -> -1756068 | E18: =D18-C18 -> 1761301 | F18: =IF(C18=0, "n.a",E18/C18) -> -0.50074388 | G18: =IS!F10 -> -2152272 | H18: =G18-D18 -> -396204 | I18: =IF(D18=0, "n.a", H18/D18) -> 0.22561996 | J18: =IF(OR(D18="", G18=""), "", IF(AND(D18<0, G18<0, G18>D18), "Decelerating", IF(AND(D18<0, G18<0, G18<D18), "Accelerating", IF(AND(D18>=0, G18>=0, G18>D18), "Decelerating", IF(AND(D18>=0, G18>=0, G18<D18), "Accelerating", IF(ABS(G18-D18)<0.01, "Stable", "Structural Break")))))) -> Accelerating | K18: 0.12 | L18: 0.16 | M18: 0.25 | O18: Bear +12.0%: Product investment is moderated to prioritize profitability and cash generation. Base +16.0%: Continued investment in platform capabilities, product enhancement, and technology infrastructure. Bull +25.0%: Accelerated investment supports new product development, platform scalability, and long-term growth initiatives. | P18: Product development remains a strategic investment area supporting platform competitiveness, ecosystem integration, and Financial Technology expansion. The pace of investment will depend on management's balance between profitability objectives and long-term innovation.
B19: Operational & Support Expenses | C19: =IS!D11 -> -1704532 | D19: =IS!E11 -> -975514 | E19: =D19-C19 -> 729018 | F19: =IF(C19=0, "n.a",E19/C19) -> -0.42769394 | G19: =IS!F11 -> -974464 | H19: =G19-D19 -> 1050 | I19: =IF(D19=0, "n.a", H19/D19) -> -0.0010763556 | J19: =IF(OR(D19="", G19=""), "", IF(AND(D19<0, G19<0, G19>D19), "Decelerating", IF(AND(D19<0, G19<0, G19<D19), "Accelerating", IF(AND(D19>=0, G19>=0, G19>D19), "Decelerating", IF(AND(D19>=0, G19>=0, G19<D19), "Accelerating", IF(ABS(G19-D19)<0.01, "Stable", "Structural Break")))))) -> Decelerating | K19: 0.02 | L19: 0.01 | M19: 0.001 | O19: Bear +2.0%: Higher operating activity results in modest increases in support costs. Base +1.0%: Expenses increase broadly in line with inflation while operational efficiencies are maintained. Bull +0.1%: Continued efficiency initiatives largely offset higher business activity, keeping support costs broadly flat. | P19: Operational support expenses are expected to remain stable due to ongoing efficiency initiatives. Incremental increases are primarily attributable to inflation and higher business volumes rather than structural cost expansion.
B20: Depreciation & Amortization | C20: =IS!D12 -> -2671148 | D20: =IS!E12 -> -744175 | E20: =D20-C20 -> 1926973 | F20: =IF(C20=0, "n.a",E20/C20) -> -0.72140256 | G20: =IS!F12 -> -748552 | H20: =G20-D20 -> -4377 | I20: =IF(D20=0, "n.a", H20/D20) -> 0.0058816811 | J20: =IF(OR(D20="", G20=""), "", IF(AND(D20<0, G20<0, G20>D20), "Decelerating", IF(AND(D20<0, G20<0, G20<D20), "Accelerating", IF(AND(D20>=0, G20>=0, G20>D20), "Decelerating", IF(AND(D20>=0, G20>=0, G20<D20), "Accelerating", IF(ABS(G20-D20)<0.01, "Stable", "Structural Break")))))) -> Accelerating | K20: 0 | L20: 0 | M20: 0 | O20: Flat | P20: Depreciation and amortization are assumed to remain broadly unchanged as the existing asset base is largely stable and no material capital expenditure or acquisition activity is incorporated into the FY2026 forecast.
B22: C. OTHER INCOME/(EXPENSE) ASSUMPTIONS
B23: Assumption / Driver | C23: FY2023A | D23: FY2024A | E23: Growth 23-24 | F23: % Growth 23-24 | G23: FY2025A | H23: Growth 24-25 | I23: % Growth 24-25 | J23: Trend | K23: FY2026F Bear | L23: FY2026F Base | M23: FY2026F Bull | O23: Scenario Assumptions | P23: Rationale
B24: Other Income / (Expenses)
B25: Finance Income | C25: =IS!D18 -> 635780 | D25: =IS!E18 -> 736449 | E25: =D25-C25 -> 100669 | F25: =IF(C25=0, "n.a",E25/C25) -> 0.15833936 | G25: =IS!F18 -> 573105 | H25: =G25-D25 -> -163344 | I25: =IF(D25=0, "n.a", H25/D25) -> -0.22179947 | J25: =IF(OR(D25="", G25=""), "", IF(AND(D25<0, G25<0, G25>D25), "Decelerating", IF(AND(D25<0, G25<0, G25<D25), "Accelerating", IF(AND(D25>=0, G25>=0, G25>D25), "Decelerating", IF(AND(D25>=0, G25>=0, G25<D25), "Accelerating", IF(ABS(G25-D25)<0.01, "Stable", "Structural Break")))))) -> Accelerating | K25: 0 | L25: 0.05 | M25: 0.1 | O25: Bear 0%: Interest income remains flat as cash balances decline or interest rates soften. Base +5%: Strong cash balances continue to generate moderate interest income. Bull +10%: Higher interest rates and effective treasury management support stronger finance income. | P25: Finance income is primarily driven by cash balances and prevailing interest rates. Moderate growth is expected given GoTo's strong liquidity position.
B26: Finance Costs | C26: =IS!D19 -> -369285 | D26: =IS!E19 -> -494053 | E26: =D26-C26 -> -124768 | F26: =IF(C26=0, "n.a",E26/C26) -> 0.33786371 | G26: =IS!F19 -> -535152 | H26: =G26-D26 -> -41099 | I26: =IF(D26=0, "n.a", H26/D26) -> 0.083187431 | J26: =IF(OR(D26="", G26=""), "", IF(AND(D26<0, G26<0, G26>D26), "Decelerating", IF(AND(D26<0, G26<0, G26<D26), "Accelerating", IF(AND(D26>=0, G26>=0, G26>D26), "Decelerating", IF(AND(D26>=0, G26>=0, G26<D26), "Accelerating", IF(ABS(G26-D26)<0.01, "Stable", "Structural Break")))))) -> Accelerating | K26: 0.08 | L26: 0.05 | M26: 0.02 | O26: Bear +8%: Higher borrowing costs or additional financing requirements increase interest expense. Base +5%: Debt levels remain broadly stable with no significant refinancing activity. Bull +2%: Improved funding costs or lower debt utilization limit interest expense growth. | P26: Finance costs are expected to remain relatively stable, with movements primarily dependent on financing activities and interest rate conditions.
B27: Foreign Exchange Gain/(Loss), net | C27: =IS!D20 -> -174214 | D27: =IS!E20 -> 289924 | E27: =D27-C27 -> 464138 | F27: =IF(C27=0, "n.a",E27/C27) -> -2.6641831 | G27: =IS!F20 -> 111862 | H27: =G27-D27 -> -178062 | I27: =IF(D27=0, "n.a", H27/D27) -> -0.61416785 | J27: =IF(OR(D27="", G27=""), "", IF(AND(D27<0, G27<0, G27>D27), "Decelerating", IF(AND(D27<0, G27<0, G27<D27), "Accelerating", IF(AND(D27>=0, G27>=0, G27>D27), "Decelerating", IF(AND(D27>=0, G27>=0, G27<D27), "Accelerating", IF(ABS(G27-D27)<0.01, "Stable", "Structural Break")))))) -> Accelerating | K27: 0 | L27: 0 | M27: 0 | O27: Bear/Base/Bull 0%: No forecast adjustment.
B28: Loss on Goodwill Impairment | C28: =IS!D21 -> -373204 | D28: =IS!E21 -> -308114 | E28: =D28-C28 -> 65090 | F28: =IF(C28=0, "n.a",E28/C28) -> -0.17440863 | G28: =IS!F21 -> -356830 | H28: =G28-D28 -> -48716 | I28: =IF(D28=0, "n.a", H28/D28) -> 0.15811031 | J28: =IF(OR(D28="", G28=""), "", IF(AND(D28<0, G28<0, G28>D28), "Decelerating", IF(AND(D28<0, G28<0, G28<D28), "Accelerating", IF(AND(D28>=0, G28>=0, G28>D28), "Decelerating", IF(AND(D28>=0, G28>=0, G28<D28), "Accelerating", IF(ABS(G28-D28)<0.01, "Stable", "Structural Break")))))) -> Accelerating | K28: 0 | L28: 0 | M28: 0 | O28: Bear/Base/Bull 0%: No impairment assumed.
B29: Loss on Impairment (Intangible+FA) | C29: =IS!D22 -> -78767510 | D29: =IS!E22 -> -24421 | E29: =D29-C29 -> 78743089 | F29: =IF(C29=0, "n.a",E29/C29) -> -0.99968996 | G29: =IS!F22 -> -217133 | H29: =G29-D29 -> -192712 | I29: =IF(D29=0, "n.a", H29/D29) -> 7.8912411 | J29: =IF(OR(D29="", G29=""), "", IF(AND(D29<0, G29<0, G29>D29), "Decelerating", IF(AND(D29<0, G29<0, G29<D29), "Accelerating", IF(AND(D29>=0, G29>=0, G29>D29), "Decelerating", IF(AND(D29>=0, G29>=0, G29<D29), "Accelerating", IF(ABS(G29-D29)<0.01, "Stable", "Structural Break")))))) -> Accelerating | K29: 0 | L29: 0 | M29: 0 | O29: Bear/Base/Bull 0%: No impairment assumed.
B30: Loss on Investment Impairment | C30: =IS!D23 -> -51625 | D30: =IS!E23 -> -126718 | E30: =D30-C30 -> -75093 | F30: =IF(C30=0, "n.a",E30/C30) -> 1.454586 | G30: =IS!F23 -> 0 | H30: =G30-D30 -> 126718 | I30: =IF(D30=0, "n.a", H30/D30) -> -1 | J30: =IF(OR(D30="", G30=""), "", IF(AND(D30<0, G30<0, G30>D30), "Decelerating", IF(AND(D30<0, G30<0, G30<D30), "Accelerating", IF(AND(D30>=0, G30>=0, G30>D30), "Decelerating", IF(AND(D30>=0, G30>=0, G30<D30), "Accelerating", IF(ABS(G30-D30)<0.01, "Stable", "Structural Break")))))) -> Structural Break | K30: 0 | L30: 0 | M30: 0 | O30: Bear/Base/Bull 0%: No impairment assumed.
B31: Fair Value Adjustment (Fin. Inst.) | C31: =IS!D24 -> -991570 | D31: =IS!E24 -> -482134 | E31: =D31-C31 -> 509436 | F31: =IF(C31=0, "n.a",E31/C31) -> -0.51376706 | G31: =IS!F24 -> -596703 | H31: =G31-D31 -> -114569 | I31: =IF(D31=0, "n.a", H31/D31) -> 0.23762896 | J31: =IF(OR(D31="", G31=""), "", IF(AND(D31<0, G31<0, G31>D31), "Decelerating", IF(AND(D31<0, G31<0, G31<D31), "Accelerating", IF(AND(D31>=0, G31>=0, G31>D31), "Decelerating", IF(AND(D31>=0, G31>=0, G31<D31), "Accelerating", IF(ABS(G31-D31)<0.01, "Stable", "Structural Break")))))) -> Accelerating | K31: 0 | L31: 0 | M31: 0 | O31: Bear/Base/Bull 0%: No forecast adjustment.
B32: Share of Net Profit/(Loss) Assoc. | C32: =IS!D25 -> -211826 | D32: =IS!E25 -> -2305125 | E32: =D32-C32 -> -2093299 | F32: =IF(C32=0, "n.a",E32/C32) -> 9.8821627 | G32: =IS!F25 -> 249100 | H32: =G32-D32 -> 2554225 | I32: =IF(D32=0, "n.a", H32/D32) -> -1.1080636 | J32: =IF(OR(D32="", G32=""), "", IF(AND(D32<0, G32<0, G32>D32), "Decelerating", IF(AND(D32<0, G32<0, G32<D32), "Accelerating", IF(AND(D32>=0, G32>=0, G32>D32), "Decelerating", IF(AND(D32>=0, G32>=0, G32<D32), "Accelerating", IF(ABS(G32-D32)<0.01, "Stable", "Structural Break")))))) -> Structural Break | K32: 0 | L32: 0.1 | M32: 0.2 | O32: Bear 0%: Associate performance remains weak. Base +10%: Tokopedia's earnings gradually stabilize. Bull +20%: Stronger profitability at Tokopedia contributes higher equity earnings. | P32: Equity income depends primarily on Tokopedia's financial performance and GoTo's ownership interest. Gradual earnings recovery is assumed under the base case.
B33: Other Income/(Expenses), net | C33: =IS!D26 -> -51994 | D33: =IS!E26 -> -320764 | E33: =D33-C33 -> -268770 | F33: =IF(C33=0, "n.a",E33/C33) -> 5.1692503 | G33: =IS!F26 -> 63401 | H33: =G33-D33 -> 384165 | I33: =IF(D33=0, "n.a", H33/D33) -> -1.1976562 | J33: =IF(OR(D33="", G33=""), "", IF(AND(D33<0, G33<0, G33>D33), "Decelerating", IF(AND(D33<0, G33<0, G33<D33), "Accelerating", IF(AND(D33>=0, G33>=0, G33>D33), "Decelerating", IF(AND(D33>=0, G33>=0, G33<D33), "Accelerating", IF(ABS(G33-D33)<0.01, "Stable", "Structural Break")))))) -> Structural Break | K33: 0 | L33: 0.05 | M33: 0.1 | O33: Bear 0%: No significant change. Base +5%: Other income and expenses remain broadly stable. Bull +10%: Slight improvement from miscellaneous non-operating items. | P33: Other non-operating items are assumed to remain broadly consistent with historical levels due to their limited predictability.

Sheet IS
B1: GOTO (GOTO.JK) — Consolidated Income Statement
B2: For the year ended 31 December | Rp Juta (IDR Millions)
B3: Line Item | C3: Note | D3: FY2023 | E3: FY2024 | F3: FY2025 | G3: Δ 23-24 Rp Juta | H3: Δ 23-24 % | I3: Δ 24-25 Rp Juta | J3: Δ 24-25 % | K3: FY2026 Bear | L3: FY2026 Base | M3: FY2026 Bull | N3: Notes
B4: NET REVENUES | C4: 25 | D4: 14785492 | E4: 15894462 | F4: 18322117 | G4: =E4-D4 -> 1108970 | H4: =G4/D4 -> 0.07500393 | I4: =F4-E4 -> 2427655 | J4: =(I4/E4) -> 0.1527359 | K4: =(ASSUMPTIONS!$G$5*(1+ASSUMPTIONS!K5))+(ASSUMPTIONS!$G$6*(1+ASSUMPTIONS!K6))+(ASSUMPTIONS!$G$7*(1+ASSUMPTIONS!K7))+(ASSUMPTIONS!$G$8*(1+ASSUMPTIONS!K8))+(ASSUMPTIONS!$G$9*(1+ASSUMPTIONS!K9))+(ASSUMPTIONS!$G$10*(1+ASSUMPTIONS!K10)) -> 19894374 | L4: =(ASSUMPTIONS!$G$5*(1+ASSUMPTIONS!L5))+(ASSUMPTIONS!$G$6*(1+ASSUMPTIONS!L6))+(ASSUMPTIONS!$G$7*(1+ASSUMPTIONS!L7))+(ASSUMPTIONS!$G$8*(1+ASSUMPTIONS!L8))+(ASSUMPTIONS!$G$9*(1+ASSUMPTIONS!L9))+(ASSUMPTIONS!$G$10*(1+ASSUMPTIONS!L10)) -> 20855399 | M4: =(ASSUMPTIONS!$G$5*(1+ASSUMPTIONS!M5))+(ASSUMPTIONS!$G$6*(1+ASSUMPTIONS!M6))+(ASSUMPTIONS!$G$7*(1+ASSUMPTIONS!M7))+(ASSUMPTIONS!$G$8*(1+ASSUMPTIONS!M8))+(ASSUMPTIONS!$G$9*(1+ASSUMPTIONS!M9))+(ASSUMPTIONS!$G$10*(1+ASSUMPTIONS!M10)) -> 22127711
B6: Costs and Expenses
B7: Cost of Revenues | C7: 26 | D7: -5093179 | E7: -7413392 | F7: -7746034 | G7: =E7-D7 -> -2320213 | H7: =G7/D7 -> 0.45555301 | I7: =F7-E7 -> -332642 | J7: =(I7/E7) -> 0.044870418 | K7: =$F7*(1+ASSUMPTIONS!K15) -> -8172065.9 | L7: =$F7*(1+ASSUMPTIONS!L15) -> -8133335.7 | M7: =$F7*(1+ASSUMPTIONS!M15) -> -8094605.5
B8: General & Administrative Expenses | C8: 26 | D8: -5647458 | E8: -4396253 | F8: -3988925 | G8: =E8-D8 -> 1251205 | H8: =G8/D8 -> -0.22155189 | I8: =F8-E8 -> 407328 | J8: =(I8/E8) -> -0.092653448 | K8: =$F8*(1+ASSUMPTIONS!K16) -> -4148482 | L8: =$F8*(1+ASSUMPTIONS!L16) -> -4068703.5 | M8: =$F8*(1+ASSUMPTIONS!M16) -> -4028814.2
B9: Sales & Marketing Expenses | C9: 26 | D9: -6430776 | E9: -2849934 | F9: -3090124 | G9: =E9-D9 -> 3580842 | H9: =G9/D9 -> -0.55682891 | I9: =F9-E9 -> -240190 | J9: =(I9/E9) -> 0.084279145 | K9: =$F9*(1+ASSUMPTIONS!K17) -> -3352784.5 | L9: =$F9*(1+ASSUMPTIONS!L17) -> -3368235.2 | M9: =$F9*(1+ASSUMPTIONS!M17) -> -3399136.4
B10: Product Development Expenses | C10: 26 | D10: -3517369 | E10: -1756068 | F10: -2152272 | G10: =E10-D10 -> 1761301 | H10: =G10/D10 -> -0.50074388 | I10: =F10-E10 -> -396204 | J10: =(I10/E10) -> 0.22561996 | K10: =$F10*(1+ASSUMPTIONS!K18) -> -2410544.6 | L10: =$F10*(1+ASSUMPTIONS!L18) -> -2496635.5 | M10: =$F10*(1+ASSUMPTIONS!M18) -> -2690340
B11: Operational & Support Expenses | C11: 26 | D11: -1704532 | E11: -975514 | F11: -974464 | G11: =E11-D11 -> 729018 | H11: =G11/D11 -> -0.42769394 | I11: =F11-E11 -> 1050 | J11: =(I11/E11) -> -0.0010763556 | K11: =$F11*(1+ASSUMPTIONS!K19) -> -993953.28 | L11: =$F11*(1+ASSUMPTIONS!L19) -> -984208.64 | M11: =$F11*(1+ASSUMPTIONS!M19) -> -975438.46
B12: Depreciation & Amortization | C12: 26 | D12: -2671148 | E12: -744175 | F12: -748552 | G12: =E12-D12 -> 1926973 | H12: =G12/D12 -> -0.72140256 | I12: =F12-E12 -> -4377 | J12: =(I12/E12) -> 0.0058816811 | K12: =$F12*(1+ASSUMPTIONS!K20) -> -748552 | L12: =$F12*(1+ASSUMPTIONS!L20) -> -748552 | M12: =$F12*(1+ASSUMPTIONS!M20) -> -748552
B13: TOTAL COSTS AND EXPENSES | D13: =SUM(D7:D12) -> -25064462 | E13: =SUM(E7:E12) -> -18135336 | F13: =SUM(F7:F12) -> -18700371 | G13: =E13-D13 -> 6929126 | H13: =G13/D13 -> -0.27645221 | I13: =F13-E13 -> -565035 | J13: =(I13/E13) -> 0.031156577 | K13: =SUM(K7:K12) -> -19826382 | L13: =SUM(L7:L12) -> -19799671 | M13: =SUM(M7:M12) -> -19936887
B15: LOSS FROM OPERATIONS | D15: =D4-(ABS(D13)) -> -10278970 | E15: =E4-(ABS(E13)) -> -2240874 | F15: =F4-(ABS(F13)) -> -378254 | G15: =E15-D15 -> 8038096 | H15: =G15/ABS(D15) -> 0.7819943 | I15: =F15-E15 -> 1862620 | J15: =(I15/ABS(E15)) -> 0.83120247 | K15: =K4-(ABS(K13)) -> 67991.38 | L15: =L4-(ABS(L13)) -> 1055728.8 | M15: =M4-(ABS(M13)) -> 2190824.7
B17: Other Income / (Expenses)
B18: Finance Income | C18: 27a | D18: 635780 | E18: 736449 | F18: 573105 | G18: =E18-D18 -> 100669 | H18: =G18/D18 -> 0.15833936 | I18: =F18-E18 -> -163344 | J18: =(I18/E18) -> -0.22179947 | K18: =$F18*(1+ASSUMPTIONS!K25) -> 573105 | L18: =$F18*(1+ASSUMPTIONS!L25) -> 601760.25 | M18: =$F18*(1+ASSUMPTIONS!M25) -> 630415.5
B19: Finance Costs | C19: 27b | D19: -369285 | E19: -494053 | F19: -535152 | G19: =E19-D19 -> -124768 | H19: =G19/D19 -> 0.33786371 | I19: =F19-E19 -> -41099 | J19: =(I19/E19) -> 0.083187431 | K19: =$F19*(1+ASSUMPTIONS!K26) -> -577964.16 | L19: =$F19*(1+ASSUMPTIONS!L26) -> -561909.6 | M19: =$F19*(1+ASSUMPTIONS!M26) -> -545855.04
B20: Foreign Exchange Gain/(Loss), net | D20: -174214 | E20: 289924 | F20: 111862 | G20: =E20-D20 -> 464138 | H20: =G20/D20 -> -2.6641831 | I20: =F20-E20 -> -178062 | J20: =(I20/E20) -> -0.61416785 | K20: =$F20*(1+ASSUMPTIONS!K27) -> 111862 | L20: =$F20*(1+ASSUMPTIONS!L27) -> 111862 | M20: =$F20*(1+ASSUMPTIONS!M27) -> 111862
B21: Loss on Goodwill Impairment | C21: 34a | D21: -373204 | E21: -308114 | F21: -356830 | G21: =E21-D21 -> 65090 | H21: =G21/D21 -> -0.17440863 | I21: =F21-E21 -> -48716 | J21: =(I21/E21) -> 0.15811031 | K21: =$F21*(1+ASSUMPTIONS!K28) -> -356830 | L21: =$F21*(1+ASSUMPTIONS!L28) -> -356830 | M21: =$F21*(1+ASSUMPTIONS!M28) -> -356830
B22: Loss on Impairment (Intangible+FA) | D22: -78767510 | E22: -24421 | F22: -217133 | G22: =E22-D22 -> 78743089 | H22: =G22/D22 -> -0.99968996 | I22: =F22-E22 -> -192712 | J22: =(I22/E22) -> 7.8912411 | K22: =$F22*(1+ASSUMPTIONS!K29) -> -217133 | L22: =$F22*(1+ASSUMPTIONS!L29) -> -217133 | M22: =$F22*(1+ASSUMPTIONS!M29) -> -217133
B23: Loss on Investment Impairment | D23: -51625 | E23: -126718 | F23: 0 | G23: =E23-D23 -> -75093 | H23: =G23/D23 -> 1.454586 | I23: =F23-E23 -> 126718 | J23: =(I23/E23) -> -1 | K23: =$F23*(1+ASSUMPTIONS!K30) -> 0 | L23: =$F23*(1+ASSUMPTIONS!L30) -> 0 | M23: =$F23*(1+ASSUMPTIONS!M30) -> 0
B24: Fair Value Adjustment (Fin. Inst.) | D24: -991570 | E24: -482134 | F24: -596703 | G24: =E24-D24 -> 509436 | H24: =G24/D24 -> -0.51376706 | I24: =F24-E24 -> -114569 | J24: =(I24/E24) -> 0.23762896 | K24: =$F24*(1+ASSUMPTIONS!K31) -> -596703 | L24: =$F24*(1+ASSUMPTIONS!L31) -> -596703 | M24: =$F24*(1+ASSUMPTIONS!M31) -> -596703
B25: Share of Net Profit/(Loss) Assoc. | D25: -211826 | E25: -2305125 | F25: 249100 | G25: =E25-D25 -> -2093299 | H25: =G25/D25 -> 9.8821627 | I25: =F25-E25 -> 2554225 | J25: =(I25/E25) -> -1.1080636 | K25: =$F25*(1+ASSUMPTIONS!K32) -> 249100 | L25: =$F25*(1+ASSUMPTIONS!L32) -> 274010 | M25: =$F25*(1+ASSUMPTIONS!M32) -> 298920
B26: Other Income/(Expenses), net | C26: 28 | D26: -51994 | E26: -320764 | F26: 63401 | G26: =E26-D26 -> -268770 | H26: =G26/D26 -> 5.1692503 | I26: =F26-E26 -> 384165 | J26: =(I26/E26) -> -1.1976562 | K26: =$F26*(1+ASSUMPTIONS!K33) -> 63401 | L26: =$F26*(1+ASSUMPTIONS!L33) -> 66571.05 | M26: =$F26*(1+ASSUMPTIONS!M33) -> 69741.1
B27: LOSS BEFORE INCOME TAX | D27: =SUM(D18:D26)+D15 -> -90634418 | E27: =SUM(E18:E26)+E15 -> -5275830 | F27: =SUM(F18:F26)+F15 -> -1086604 | G27: =E27-D27 -> 85358588 | H27: =G27/ABS(D27) -> 0.94178999 | I27: =F27-E27 -> 4189226 | J27: =(I27/ABS(E27)) -> 0.79404113 | K27: =SUM(K18:K26)+K15 -> -683170.78 | L27: =SUM(L18:L26)+L15 -> 377356.51 | M27: =SUM(M18:M26)+M15 -> 1585242.3
B29: Income Tax Expense | C29: 11c | D29: 115692 | E29: -189025 | F29: -415081 | G29: =E29-D29 -> -304717 | H29: =G29/D29 -> -2.6338641 | I29: =F29-E29 -> -226056 | J29: =(I29/E29) -> 1.1959053 | K29: 0 | L29: 0 | M29: 0 | N29: The Company continues to have accumulated tax loss carryforwards; therefore, cash tax expense is expected to remain minimal.
B31: LOSS FOR THE YEAR | D31: =D27+D29 -> -90518726 | E31: =E27+E29 -> -5464855 | F31: =F27+F29 -> -1501685 | G31: =E31-D31 -> 85053871 | H31: =G31/ABS(D31) -> 0.93962735 | I31: =F31-E31 -> 3963170 | J31: =(I31/ABS(E31)) -> 0.72521046 | K31: =K27 -> -683170.78 | L31: =L27 -> 377356.51 | M31: =M27 -> 1585242.3
B33: Attributable to:
B34: Owners of the Parent | D34: -90395629 | E34: -5154924 | F34: -1185654 | G34: =D34-E34 -> -85240705 | H34: =G34/D34 -> 0.94297375 | I34: =F34-E34 -> 3969270 | J34: =(I34/E34) -> -0.76999583
B35: Non-Controlling Interests | D35: -123097 | E35: -309931 | F35: -316031 | G35: =D35-E35 -> 186834 | H35: =G35/D35 -> -1.5177787 | I35: =F35-E35 -> -6100 | J35: =(I35/E35) -> 0.0196818
B37: Loss per Share — Basic & Diluted (Rp, full amount) | C37: 31 | D37: -85 | E37: -4.8 | F37: -1.1
B39: ── MEMO ITEMS ──────────────────────
B40: Gross Profit | D40: =D4-(-D7) -> 9692313 | E40: =E4-(-E7) -> 8481070 | F40: =F4-(-F7) -> 10576083 | K40: =K4-(-K7) -> 11722308 | L40: =L4-(-L7) -> 12722064 | M40: =M4-(-M7) -> 14033106
B41: Gross Profit Margin (%) | D41: =D40/D4 -> 0.65552861 | E41: =E40/E4 -> 0.53358648 | F41: =F40/F4 -> 0.5772304 | K41: =K40/K4 -> 0.58922729 | L41: =L40/L4 -> 0.61001295 | M41: =M40/M4 -> 0.63418695
B42: Operating Loss Margin (%) | D42: =D15/D4 -> -0.69520649 | E42: =E15/E4 -> -0.14098458 | F42: =F15/F4 -> -0.020644667 | K42: =K15/K4 -> 0.0034176185 | L42: =L15/L4 -> 0.050621366 | M42: =M15/M4 -> 0.099008193
B43: Net Loss Margin (%) | D43: =D27/D4 -> -6.1299562 | E43: =E27/E4 -> -0.33192882 | F43: =F27/F4 -> -0.059305592 | K43: =K27/K4 -> -0.034339899 | L43: =L27/L4 -> 0.018093948 | M43: =M27/M4 -> 0.071640589
B44: EBITDA (Operating Loss + D&A) | D44: =D15-D12 -> -7607822 | E44: =E15-E12 -> -1496699 | F44: =F15-F12 -> 370298 | K44: =K15-K12 -> 816543.38 | L44: =L15-L12 -> 1804280.8 | M44: =M15-M12 -> 2939376.7
B45: EBITDA Margin (%) | D45: =D44/D4 -> -0.51454642 | E45: =E44/E4 -> -0.09416481 | F45: =F44/F4 -> 0.020210437 | K45: =K44/K4 -> 0.041043935 | L45: =L44/L4 -> 0.086513846 | M45: =M44/M4 -> 0.13283691
B46: ── ADDITIONAL ──────────────────────
B47: Operating Cash Flow | D47: =CF!D60 -> -4325308 | E47: =CF!E60 -> -622114 | F47: =CF!F60 -> 307025 | K47: =K44*(($F48+$E48+$D48)/3) -> 493551.82 | L47: =L44*(($F48+$E48+$D48)/3) -> 1090580.2 | M47: =M44*(($F48+$E48+$D48)/3) -> 1776678.1
B48: Ratio OCF | D48: =D47/D44 -> 0.56853433 | E48: =E47/E44 -> 0.41565739 | F48: =F47/F44 -> 0.82912951 | K48: =($E$48+$F$48)/2 -> 0.62239345 | L48: =($E$48+$F$48)/2 -> 0.62239345 | M48: =($E$48+$F$48)/2 -> 0.62239345
...

Sheet BS
B1: GOTO (GOTO.JK) — Consolidated Balance Sheet (Statement of Financial Position)
B2: As of 31 December | Rp Juta (IDR Millions)
B3: Line Item | C3: Note | D3: FY2023 | E3: FY2024 | F3: FY2025 | G3: Δ 23-24 Rp Juta | H3: Δ 23-24 % | I3: Δ 24-25 Rp Juta | J3: Δ 24-25 %
B4: ASSETS
B5: CURRENT ASSETS
B6: Cash & Cash Equivalents | C6: 4 | D6: 25143935 | E6: 19177524 | F6: 21755165 | G6: =E6-D6 -> -5966411 | H6: =IF(D6=0,"n.a",(G6/D6)) -> -0.23729027 | I6: =F6-E6 -> 2577641 | J6: =IF(E6=0, "n.a", I6/E6) -> 0.13440948
B7: Time Deposits | C7: 5 | D7: 2225788 | E7: 1747595 | F7: 304955 | G7: =E7-D7 -> -478193 | H7: =IF(D7=0,"n.a",(G7/D7)) -> -0.21484211 | I7: =F7-E7 -> -1442640 | J7: =IF(E7=0, "n.a", I7/E7) -> -0.82550019
B8: Restricted Cash | C8: 20a | D8: 0 | E8: 1000000 | F8: 1000000 | G8: =E8-D8 -> 1000000 | H8: =IF(D8=0,"n.a",(G8/D8)) -> n.a | I8: =F8-E8 -> 0 | J8: =IF(E8=0, "n.a", I8/E8) -> 0
B9: Trade Receivables — Third Parties | C9: 6 | D9: 598017 | E9: 260228 | F9: 268342 | G9: =E9-D9 -> -337789 | H9: =IF(D9=0,"n.a",(G9/D9)) -> -0.56484849 | I9: =F9-E9 -> 8114 | J9: =IF(E9=0, "n.a", I9/E9) -> 0.03118035
B10: Trade Receivables — Related Parties | C10: 30c | D10: 3227 | E10: 199741 | F10: 278951 | G10: =E10-D10 -> 196514 | H10: =IF(D10=0,"n.a",(G10/D10)) -> 60.896808 | I10: =F10-E10 -> 79210 | J10: =IF(E10=0, "n.a", I10/E10) -> 0.39656355
B11: Financing & Lending Receivables | C11: 7 | D11: 505161 | E11: 1581770 | F11: 2730813 | G11: =E11-D11 -> 1076609 | H11: =IF(D11=0,"n.a",(G11/D11)) -> 2.1312196 | I11: =F11-E11 -> 1149043 | J11: =IF(E11=0, "n.a", I11/E11) -> 0.72642862
B12: Other Receivables — Third Parties | C12: 8 | D12: 1965265 | E12: 1025454 | F12: 1237595 | G12: =E12-D12 -> -939811 | H12: =IF(D12=0,"n.a",(G12/D12)) -> -0.47821083 | I12: =F12-E12 -> 212141 | J12: =IF(E12=0, "n.a", I12/E12) -> 0.2068752
B13: Other Receivables — Related Parties | C13: 8 | D13: 247024 | E13: 392502 | F13: 463818 | G13: =E13-D13 -> 145478 | H13: =IF(D13=0,"n.a",(G13/D13)) -> 0.58892253 | I13: =F13-E13 -> 71316 | J13: =IF(E13=0, "n.a", I13/E13) -> 0.18169589
B14: Inventories | C14: 9 | D14: 71426 | E14: 27404 | F14: 14093 | G14: =E14-D14 -> -44022 | H14: =IF(D14=0,"n.a",(G14/D14)) -> -0.61633019 | I14: =F14-E14 -> -13311 | J14: =IF(E14=0, "n.a", I14/E14) -> -0.48573201
B15: Advances | C15: 10a | D15: 1256234 | E15: 66853 | F15: 177814 | G15: =E15-D15 -> -1189381 | H15: =IF(D15=0,"n.a",(G15/D15)) -> -0.946783 | I15: =F15-E15 -> 110961 | J15: =IF(E15=0, "n.a", I15/E15) -> 1.6597759
B16: Prepayments | C16: 10b | D16: 288174 | E16: 138103 | F16: 196792 | G16: =E16-D16 -> -150071 | H16: =IF(D16=0,"n.a",(G16/D16)) -> -0.52076523 | I16: =F16-E16 -> 58689 | J16: =IF(E16=0, "n.a", I16/E16) -> 0.42496542
B17: Prepaid Taxes (Corp. Income Tax) | C17: 11a | D17: 23858 | E17: 6561 | F17: 8188 | G17: =E17-D17 -> -17297 | H17: =IF(D17=0,"n.a",(G17/D17)) -> -0.7249979 | I17: =F17-E17 -> 1627 | J17: =IF(E17=0, "n.a", I17/E17) -> 0.24798049
... B19: Other Investments | C19: 15 | D19: 388611 | E19: 2840 | F19: 797 | G19: =E19-D19 -> -385771 | H19: =IF(D19=0,"n.a",(G19/D19)) -> -0.99269192 | I19: =F19-E19 -> -2043 | J19: =IF(E19=0, "n.a", I19/E19) -> -0.7193662
B20: Other Current Assets | D20: 10114 | E20: 0 | F20: 0 | G20: =E20-D20 -> -10114 | H20: =IF(D20=0,"n.a",(G20/D20)) -> -1 | I20: =F20-E20 -> 0 | J20: =IF(E20=0, "n.a", I20/E20) -> n.a
B21: TOTAL CURRENT ASSETS | D21: =SUM(D6:D20) -> 33617291 | E21: =SUM(E6:E20) -> 26337692 | F21: =SUM(F6:F20) -> 29059226 | G21: =E21-D21 -> -7279599 | H21: =IF(D21=0,"n.a",(G21/D21)) -> -0.2165433 | I21: =F21-E21 -> 2721534 | J21: =IF(E21=0, "n.a", I21/E21) -> 0.10333229
B23: NON-CURRENT ASSETS
B24: Other Receivables (non-current) | C24: 8 | D24: 146208 | E24: 607599 | F24: 461835 | G24: =E24-D24 -> 461391 | H24: =IF(D24=0,"n.a",(G24/D24)) -> 3.1557165 | I24: =F24-E24 -> -145764 | J24: =IF(E24=0, "n.a", I24/E24) -> -0.23990165
B25: Intangible Assets | C25: 12 | D25: 8036379 | E25: 1451268 | F25: 1565101 | G25: =E25-D25 -> -6585111 | H25: =IF(D25=0,"n.a",(G25/D25)) -> -0.8194127 | I25: =F25-E25 -> 113833 | J25: =IF(E25=0, "n.a", I25/E25) -> 0.078436926
B26: Fixed Assets | C26: 13 | D26: 1038618 | E26: 456997 | F26: 622356 | G26: =E26-D26 -> -581621 | H26: =IF(D26=0,"n.a",(G26/D26)) -> -0.55999511 | I26: =F26-E26 -> 165359 | J26: =IF(E26=0, "n.a", I26/E26) -> 0.36183826
B27: Investment in Associates | C27: 14 | D27: 3119605 | E27: 10416327 | F27: 10594799 | G27: =E27-D27 -> 7296722 | H27: =IF(D27=0,"n.a",(G27/D27)) -> 2.3389891 | I27: =F27-E27 -> 178472 | J27: =IF(E27=0, "n.a", I27/E27) -> 0.017133871
B28: Investment in Joint Ventures | D28: 360693 | E28: 411108 | F28: 503054 | G28: =E28-D28 -> 50415 | H28: =IF(D28=0,"n.a",(G28/D28)) -> 0.1397726 | I28: =F28-E28 -> 91946 | J28: =IF(E28=0, "n.a", I28/E28) -> 0.22365412
B29: Other Investments (non-current) | C29: 15 | D29: 3581563 | E29: 3047655 | F29: 2327235 | G29: =E29-D29 -> -533908 | H29: =IF(D29=0,"n.a",(G29/D29)) -> -0.14907123 | I29: =F29-E29 -> -720420 | J29: =IF(E29=0, "n.a", I29/E29) -> -0.23638502
B30: Deferred Tax Assets | C30: 11d | D30: 12639 | E30: 5421 | F30: 54079 | G30: =E30-D30 -> -7218 | H30: =IF(D30=0,"n.a",(G30/D30)) -> -0.57108948 | I30: =F30-E30 -> 48658 | J30: =IF(E30=0, "n.a", I30/E30) -> 8.9758347
B31: Goodwill | C31: 34a | D31: 4065549 | E31: 372575 | F31: 15745 | G31: =E31-D31 -> -3692974 | H31: =IF(D31=0,"n.a",(G31/D31)) -> -0.90835801 | I31: =F31-E31 -> -356830 | J31: =IF(E31=0, "n.a", I31/E31) -> -0.95774005
B32: Other Non-Current Assets | D32: 118711 | E32: 101242 | F32: 554212 | G32: =E32-D32 -> -17469 | H32: =IF(D32=0,"n.a",(G32/D32)) -> -0.1471557 | I32: =F32-E32 -> 452970 | J32: =IF(E32=0, "n.a", I32/E32) -> 4.4741313
B33: TOTAL NON-CURRENT ASSETS | D33: =SUM(D24:D32) -> 20479965 | E33: =SUM(E24:E32) -> 16870192 | F33: =SUM(F24:F32) -> 16698416 | G33: =E33-D33 -> -3609773 | H33: =IF(D33=0,"n.a",(G33/D33)) -> -0.17625875 | I33: =F33-E33 -> -171776 | J33: =IF(E33=0, "n.a", I33/E33) -> -0.01018222
B35: TOTAL ASSETS | D35: =D21+D33 -> 54097256 | E35: =E21+E33 -> 43207884 | F35: =F21+F33 -> 45757642 | G35: =E35-D35 -> -10889372 | H35: =IF(OR(D35=0,E35=0),"n.a",(G35/D35)) -> -0.2012925 | I35: =F35-E35 -> 2549758 | J35: =IF(E35=0, "n.a", I35/E35) -> 0.059011406
B37: LIABILITIES & EQUITY
B38: CURRENT LIABILITIES
B39: Trade Payables — Third Parties | C39: 16 | D39: 1341240 | E39: 1054163 | F39: 1129649 | G39: =E39-D39 -> -287077 | H39: =IF(D39=0,"n.a",(G39/D39)) -> -0.2140385 | I39: =F39-E39 -> 75486 | J39: =IF(E39=0, "n.a", I39/E39) -> 0.071607522
B40: Trade Payables — Related Parties | C40: 30c | D40: 0 | E40: 186722 | F40: 124740 | G40: =E40-D40 -> 186722 | H40: =IF(D40=0,"n.a",(G40/D40)) -> n.a | I40: =F40-E40 -> -61982 | J40: =IF(E40=0, "n.a", I40/E40) -> -0.33194803
B41: Escrow & Other Payables — Third Parties | C41: 17 | D41: 5380396 | E41: 2310683 | F41: 2623458 | G41: =E41-D41 -> -3069713 | H41: =IF(D41=0,"n.a",(G41/D41)) -> -0.57053663 | I41: =F41-E41 -> 312775 | J41: =IF(E41=0, "n.a", I41/E41) -> 0.13536041
B42: Escrow & Other Payables — Related Parties | C42: 17 | D42: 117635 | E42: 241097 | F42: 419920 | G42: =E42-D42 -> 123462 | H42: =IF(D42=0,"n.a",(G42/D42)) -> 1.0495346 | I42: =F42-E42 -> 178823 | J42: =IF(E42=0, "n.a", I42/E42) -> 0.74170562
B43: Deferred Revenue | C43: 25 | D43: 205208 | E43: 78198 | F43: 69012 | G43: =E43-D43 -> -127010 | H43: =IF(D43=0,"n.a",(G43/D43)) -> -0.61893299 | I43: =F43-E43 -> -9186 | J43: =IF(E43=0, "n.a", I43/E43) -> -0.11747104
B44: Accruals | C44: 18 | D44: 4027375 | E44: 3314874 | F44: 3939255 | G44: =E44-D44 -> -712501 | H44: =IF(D44=0,"n.a",(G44/D44)) -> -0.17691449 | I44: =F44-E44 -> 624381 | J44: =IF(E44=0, "n.a", I44/E44) -> 0.18835739
...

Sheet CF
B1: GOTO (GOTO.JK) — Consolidated Statement of Cash Flows
B2: For the year ended 31 December | Rp Juta (IDR Millions) | Direct Method
B3: Line Item | C3: Note | D3: FY2023 | E3: FY2024 | F3: FY2025 | G3: Δ 23-24 Rp Juta | H3: Δ 23-24 % | I3: Δ 24-25 Rp Juta | J3: Δ 24-25 %
B4: OPERATING ACTIVITIES
B5: Cash receipts from customers | D5: 23748122 | E5: 18880338 | F5: 20931399 | G5: =E5-D5 -> -4867784 | H5: =IF(D5=0,"n.a",G5/D5) -> -0.20497553 | I5: =F5-E5 -> 2051061 | J5: =IF(E5=0,"n.a", I5/E5) -> 0.10863476
B6: Payments to customers | D6: -12822461 | E6: -4784853 | F6: -3956973 | G6: =E6-D6 -> 8037608 | H6: =IF(D6=0,"n.a",G6/D6) -> -0.62683817 | I6: =F6-E6 -> 827880 | J6: =IF(E6=0,"n.a", I6/E6) -> -0.17302099
B7: Payments to suppliers | D7: -2233673 | E7: -5784605 | F7: -5701503 | G7: =E7-D7 -> -3550932 | H7: =IF(D7=0,"n.a",G7/D7) -> 1.5897278 | I7: =F7-E7 -> 83102 | J7: =IF(E7=0,"n.a", I7/E7) -> -0.014366063
B8: Users net-off | D8: -266652 | E8: -24042 | F8: 178674 | G8: =E8-D8 -> 242610 | H8: =IF(D8=0,"n.a",G8/D8) -> -0.90983754 | I8: =F8-E8 -> 202716 | J8: =IF(E8=0,"n.a", I8/E8) -> -8.4317444
B9: Financing & lending disbursed to users, net | D9: 0 | E9: -1229186 | F9: -2019761 | G9: =E9-D9 -> -1229186 | H9: =IF(D9=0,"n.a",G9/D9) -> n.a | I9: =F9-E9 -> -790575 | J9: =IF(E9=0,"n.a", I9/E9) -> 0.64316954
B10: Payments to employees | D10: -5337034 | E10: -3321854 | F10: -3353512 | G10: =E10-D10 -> 2015180 | H10: =IF(D10=0,"n.a",G10/D10) -> -0.37758425 | I10: =F10-E10 -> -31658 | J10: =IF(E10=0,"n.a", I10/E10) -> 0.0095302202
B11: Other payments | D11: -7422939 | E11: -4655285 | F11: -5578054 | G11: =E11-D11 -> 2767654 | H11: =IF(D11=0,"n.a",G11/D11) -> -0.37285151 | I11: =F11-E11 -> -922769 | J11: =IF(E11=0,"n.a", I11/E11) -> 0.19821966
B12: Cash from/(used in) Operations (before tax) | D12: =SUM(D5:D11) -> -4334637 | E12: =SUM(E5:E11) -> -919487 | F12: =SUM(F5:F11) -> 500270 | G12: =E12-D12 -> 3415150 | H12: =IF(D12=0,"n.a",G12/D12) -> -0.78787451 | I12: =F12-E12 -> 1419757 | J12: =IF(E12=0,"n.a", I12/E12) -> -1.5440751
B13: Corporate income tax paid | D13: -277118 | E13: -88466 | F13: -433486 | G13: =E13-D13 -> 188652 | H13: =IF(D13=0,"n.a",G13/D13) -> -0.68076415 | I13: =F13-E13 -> -345020 | J13: =IF(E13=0,"n.a", I13/E13) -> 3.9000294
B14: Finance income received | D14: 582161 | E14: 700446 | F14: 546368 | G14: =E14-D14 -> 118285 | H14: =IF(D14=0,"n.a",G14/D14) -> 0.20318262 | I14: =F14-E14 -> -154078 | J14: =IF(E14=0,"n.a", I14/E14) -> -0.21997128
B15: Finance costs paid | D15: -295714 | E15: -314607 | F15: -306127 | G15: =E15-D15 -> -18893 | H15: =IF(D15=0,"n.a",G15/D15) -> 0.063889434 | I15: =F15-E15 -> 8480 | J15: =IF(E15=0,"n.a", I15/E15) -> -0.026954264
B16: NET CASH FROM/(USED IN) OPERATING ACTIVITIES | D16: =SUM(D12:D15) -> -4325308 | E16: =SUM(E12:E15) -> -622114 | F16: =SUM(F12:F15) -> 307025 | G16: =E16-D16 -> 3703194 | H16: =IF(D16=0,"n.a",G16/D16) -> -0.85616886 | I16: =F16-E16 -> 929139 | J16: =IF(E16=0,"n.a", I16/E16) -> -1.4935189
B18: INVESTING ACTIVITIES
B19: Purchase of intangible assets | D19: -49047 | E19: -6339296 | F19: -880289 | G19: =E19-D19 -> -6290249 | H19: =IF(D19=0,"n.a",G19/D19) -> 128.24941 | I19: =F19-E19 -> 5459007 | J19: =IF(E19=0,"n.a", I19/E19) -> -0.86113774
B20: Purchase of fixed assets | D20: -171400 | E20: -179566 | F20: -302071 | G20: =E20-D20 -> -8166 | H20: =IF(D20=0,"n.a",G20/D20) -> 0.04764294 | I20: =F20-E20 -> -122505 | J20: =IF(E20=0,"n.a", I20/E20) -> 0.68222826
B21: Proceeds from sale of fixed assets | D21: 19968 | E21: 3341 | F21: 0 | G21: =E21-D21 -> -16627 | H21: =IF(D21=0,"n.a",G21/D21) -> -0.83268229 | I21: =F21-E21 -> -3341 | J21: =IF(E21=0,"n.a", I21/E21) -> -1
B22: Addition of investments in assoc./JV | D22: -42625 | E22: -2200 | F22: -16283 | G22: =E22-D22 -> 40425 | H22: =IF(D22=0,"n.a",G22/D22) -> -0.9483871 | I22: =F22-E22 -> -14083 | J22: =IF(E22=0,"n.a", I22/E22) -> 6.4013636
B23: Proceeds from sale of investments in JV | D23: 2901 | E23: 0 | F23: 3720 | G23: =E23-D23 -> -2901 | H23: =IF(D23=0,"n.a",G23/D23) -> -1 | I23: =F23-E23 -> 3720 | J23: =IF(E23=0,"n.a", I23/E23) -> n.a
B24: Addition of loans to third parties | D24: -623762 | E24: -44093 | F24: -4626 | G24: =E24-D24 -> 579669 | H24: =IF(D24=0,"n.a",G24/D24) -> -0.92931118 | I24: =F24-E24 -> 39467 | J24: =IF(E24=0,"n.a", I24/E24) -> -0.89508539
B25: Addition of loans to related parties | D25: -45000 | E25: 0 | F25: 0 | G25: =E25-D25 -> 45000 | H25: =IF(D25=0,"n.a",G25/D25) -> -1 | I25: =F25-E25 -> 0 | J25: =IF(E25=0,"n.a", I25/E25) -> n.a
B26: Receipt from loans provided for thhird parties | D26: 765976 | E26: 334293 | F26: 110532 | G26: =E26-D26 -> -431683 | H26: =IF(D26=0,"n.a",G26/D26) -> -0.56357249 | I26: =F26-E26 -> -223761 | J26: =IF(E26=0,"n.a", I26/E26) -> -0.66935592
B27: Net cash on loss of control in subsidiary | D27: -189754 | E27: -4006527 | F27: 0 | G27: =E27-D27 -> -3816773 | H27: =IF(D27=0,"n.a",G27/D27) -> 20.114322 | I27: =F27-E27 -> 4006527 | J27: =IF(E27=0,"n.a", I27/E27) -> -1
B28: Proceeds from disposal of subsidiary interest | D28: 0 | E28: 0 | F28: 59804 | G28: =E28-D28 -> 0 | H28: =IF(D28=0,"n.a",G28/D28) -> n.a | I28: =F28-E28 -> 59804 | J28: =IF(E28=0,"n.a", I28/E28) -> n.a
B29: Receipt of advance from sale of investment | D29: 0 | E29: 0 | F29: 20138 | G29: =E29-D29 -> 0 | H29: =IF(D29=0,"n.a",G29/D29) -> n.a | I29: =F29-E29 -> 20138 | J29: =IF(E29=0,"n.a", I29/E29) -> n.a
B30: Payment for acquisition of subsidiary, net | D30: 0 | E30: -83904 | F30: 0 | G30: =E30-D30 -> -83904 | H30: =IF(D30=0,"n.a",G30/D30) -> n.a | I30: =F30-E30 -> 83904 | J30: =IF(E30=0,"n.a", I30/E30) -> -1
... B37: Proceeds from return of capital on financial assets | D37: 17121 | E37: 3582 | F37: 94458 | G37: =E37-D37 -> -13539 | H37: =IF(D37=0,"n.a",G37/D37) -> -0.79078325 | I37: =F37-E37 -> 90876 | J37: =IF(E37=0,"n.a", I37/E37) -> 25.370184
B38: NET CASH FROM/(USED IN) INVESTING ACTIVITIES | D38: =SUM(D19:D37) -> -1472030 | E38: =SUM(E19:E37) -> -10324679 | F38: =SUM(F19:F37) -> 519117 | G38: =E38-D38 -> -8852649 | H38: =IF(D38=0,"n.a",G38/D38) -> 6.0139053 | I38: =F38-E38 -> 10843796 | J38: =IF(E38=0,"n.a", I38/E38) -> -1.0502792
B40: FINANCING ACTIVITIES
B41: Proceeds from third-party loans | C41: 32 | D41: 0 | E41: 6381860 | F41: 3718013 | G41: =E41-D41 -> 6381860 | H41: =IF(D41=0,"n.a",G41/D41) -> n.a | I41: =F41-E41 -> -2663847 | J41: =IF(E41=0,"n.a", I41/E41) -> -0.41740919
B42: Transaction costs on loans | C42: 32 | D42: 0 | E42: 0 | F42: -98240 | G42: =E42-D42 -> 0 | H42: =IF(D42=0,"n.a",G42/D42) -> n.a | I42: =F42-E42 -> -98240 | J42: =IF(E42=0,"n.a", I42/E42) -> n.a
B43: Repayment of third-party loans | C43: 32 | D43: -455622 | E43: -434000 | F43: -682000 | G43: =E43-D43 -> 21622 | H43: =IF(D43=0,"n.a",G43/D43) -> -0.047456005 | I43: =F43-E43 -> -248000 | J43: =IF(E43=0,"n.a", I43/E43) -> 0.57142857
B44: Payment of lease liabilities (principal) | C44: 32 | D44: -182015 | E44: -104284 | F44: -85090 | G44: =E44-D44 -> 77731 | H44: =IF(D44=0,"n.a",G44/D44) -> -0.42705821 | I44: =F44-E44 -> 19194 | J44: =IF(E44=0,"n.a", I44/E44) -> -0.18405508
B45: Acquisition of NCI | D45: -45291 | E45: -32453 | F45: -45592 | G45: =E45-D45 -> 12838 | H45: =IF(D45=0,"n.a",G45/D45) -> -0.28345587 | I45: =F45-E45 -> -13139 | J45: =IF(E45=0,"n.a", I45/E45) -> 0.40486242
B46: Capital injection from NCI | D46: 27000 | E46: 20592 | F46: 0 | G46: =E46-D46 -> -6408 | H46: =IF(D46=0,"n.a",G46/D46) -> -0.23733333 | I46: =F46-E46 -> -20592 | J46: =IF(E46=0,"n.a", I46/E46) -> -1
B47: Proceeds from disposal of interest in subsidiary | D47: 0 | E47: 38427 | F47: 0 | G47: =E47-D47 -> 38427 | H47: =IF(D47=0,"n.a",G47/D47) -> n.a | I47: =F47-E47 -> -38427 | J47: =IF(E47=0,"n.a", I47/E47) -> -1
B48: Acquisition of treasury shares | C48: 22 | D48: 0 | E48: -1199693 | F48: -971404 | G48: =E48-D48 -> -1199693 | H48: =IF(D48=0,"n.a",G48/D48) -> n.a | I48: =F48-E48 -> 228289 | J48: =IF(E48=0,"n.a", I48/E48) -> -0.19028952
...

Sheet SEGMENT
B1: GOTO (GOTO.JK) — Segment Review
B2: Source: Note 25 & Segment Information | Rp Juta (IDR Millions)
B3: Segment | C3: FY2023 | D3: FY2024 | E3: FY2025 | F3: YoY 23-24 Rp | G3: YoY 23-24 % | H3: Mix % FY2024 | I3: YoY 24-25 Rp | J3: YoY 24-25 % | K3: Mix % FY2025 | L3: FY2026 Bear | M3: FY2026 Base | N3: FY2026 Bull
B4: NET REVENUE BY SEGMENT
B5: Delivery Services | C5: 2131131 | D5: 5344984 | E5: 5779206 | F5: =D5-C5 -> 3213853 | G5: =IF(C5=0,100%,F5/ABS(C5)) -> 1.5080504 | H5: =D5/$D$11 -> 0.33627964 | I5: =E5-D5 -> 434222 | J5: =I5/D5 -> 0.081239158 | K5: =E5/$E$11 -> 0.31542239 | L5: =$E5*(1+ASSUMPTIONS!K5) -> 6068166.3 | M5: =$E5*(1+ASSUMPTIONS!L5) -> 6212646.5 | N5: =$E5*(1+ASSUMPTIONS!M5) -> 6299334.5
B6: Service Fee | C6: 8665040 | D6: 5801835 | E6: 5689230 | F6: =D6-C6 -> -2863205 | G6: =IF(C6=0,100%,F6/ABS(C6)) -> -0.33043183 | H6: =D6/$D$11 -> 0.36502242 | I6: =E6-D6 -> -112605 | J6: =I6/D6 -> -0.019408515 | K6: =E6/$E$11 -> 0.31051161 | L6: =$E6*(1+ASSUMPTIONS!K6) -> 5518553.1 | M6: =$E6*(1+ASSUMPTIONS!L6) -> 5632337.7 | N6: =$E6*(1+ASSUMPTIONS!M6) -> 5746122.3
B7: Lending | C7: 409955 | D7: 1935389 | E7: 3780801 | F7: =D7-C7 -> 1525434 | G7: =IF(C7=0,100%,F7/ABS(C7)) -> 3.7209791 | H7: =D7/$D$11 -> 0.12176499 | I7: =E7-D7 -> 1845412 | J7: =I7/D7 -> 0.9535096 | K7: =E7/$E$11 -> 0.20635176 | L7: =$E7*(1+ASSUMPTIONS!K7) -> 5104081.4 | M7: =$E7*(1+ASSUMPTIONS!L7) -> 5671201.5 | N7: =$E7*(1+ASSUMPTIONS!M7) -> 6616401.8
B8: E-commerce Service Fee | C8: 0 | D8: 621871 | E8: 819724 | F8: =D8-C8 -> 621871 | G8: =IF(C8=0,100%,F8/ABS(C8)) -> 1 | H8: =D8/$D$11 -> 0.039125011 | I8: =E8-D8 -> 197853 | J8: =I8/D8 -> 0.31815762 | K8: =E8/$E$11 -> 0.04473959 | L8: =$E8*(1+ASSUMPTIONS!K8) -> 942682.6 | M8: =$E8*(1+ASSUMPTIONS!L8) -> 1000063.3 | N8: =$E8*(1+ASSUMPTIONS!M8) -> 1065641.2
B9: Advertising Fee | C9: 2195135 | D9: 554997 | E9: 533268 | F9: =D9-C9 -> -1640138 | G9: =IF(C9=0,100%,F9/ABS(C9)) -> -0.74716954 | H9: =D9/$D$11 -> 0.034917634 | I9: =E9-D9 -> -21729 | J9: =I9/D9 -> -0.039151563 | K9: =E9/$E$11 -> 0.029105152 | L9: =$E9*(1+ASSUMPTIONS!K9) -> 506604.6 | M9: =$E9*(1+ASSUMPTIONS!L9) -> 533268 | N9: =$E9*(1+ASSUMPTIONS!M9) -> 559931.4
B10: Others | C10: 1384231 | D10: 1635386 | E10: 1719888 | F10: =D10-C10 -> 251155 | G10: =IF(C10=0,100%,F10/ABS(C10)) -> 0.18144009 | H10: =D10/$D$11 -> 0.1028903 | I10: =E10-D10 -> 84502 | J10: =I10/D10 -> 0.051670982 | K10: =E10/$E$11 -> 0.093869502 | L10: =$E10*(1+ASSUMPTIONS!K10) -> 1754285.8 | M10: =$E10*(1+ASSUMPTIONS!L10) -> 1805882.4 | N10: =$E10*(1+ASSUMPTIONS!M10) -> 1840280.2
B11: Total Revenue | C11: =SUM(C5:C10) -> 14785492 | D11: =SUM(D5:D10) -> 15894462 | E11: =SUM(E5:E10) -> 18322117 | F11: =SUM(F5:F10) -> 1108970 | G11: =F11/C11 -> 0.07500393 | H11: =SUM(H5:H10) -> 1 | I11: =E11-D11 -> 2427655 | J11: =I11/D11 -> 0.1527359 | K11: =E11/$E$11 -> 1 | L11: =SUM(L5:L10) -> 19894374 | M11: =SUM(M5:M10) -> 20855399 | N11: =SUM(N5:N10) -> 22127711

Sheet KPI
B1: GOTO (GOTO.JK) — KPI Summary Dashboard
B2: Key Performance Indicators | Cross-linked from IS / BS / CF / SEGMENT sheets
B3: KPI | C3: FY2024 | D3: FY2025 | E3: Trend | F3: Analyst Comment
B4: ── SCALE & GROWTH ──────────────
B5: Net Revenue (Rp Millions) | C5: =IS!E4 -> 15894462 | D5: =IS!F4 -> 18322117 | E5: =IF(D5-C5>0, "↑", "↓") -> ↑ | F5: Revenue growth remained resilient following the Tokopedia deconsolidation, indicating that GoTo's core businesses continue to generate sustainable top-line growth.
B6: YoY Revenue Growth (%) | C6: =IS!H4 -> 0.07500393 | D6: =IS!J4 -> 0.1527359 | E6: =IF(D6-C6>0, "↑", "↓") -> ↑
B8: ── PROFITABILITY JOURNEY ───────
B9: Gross Profit (Rp Millions) | C9: =IS!E4-(ABS(IS!E7)) -> 8481070 | D9: =IS!F4-(ABS(IS!F7)) -> 10576083 | E9: =IF(D9-C9>0, "↑", "↓") -> ↑ | F9: Gross profit expansion reflects stronger revenue growth combined with continued expansion in cost margin and operating leverage.
B10: Gross Profit Margin (%) | C10: =C9/IS!E4 -> 0.53358648 | D10: =D9/IS!F4 -> 0.5772304 | E10: =IF(D10-C10>0, "↑", "↓") -> ↑
B11: Operating Loss (Rp Millions) | C11: =IS!E15 -> -2240874 | D11: =IS!F15 -> -378254 | E11: =IF(D11-C11>0, "↑", "↓") -> ↑ | F11: Operating losses narrowed significantly, bringing the Company closer to operating break-even as profitability initiatives continue to gain traction.
B12: Net Loss (Rp Millions) | C12: =IS!E31 -> -5464855 | D12: =IS!F31 -> -1501685 | E12: =IF(D12-C12>0, "↑", "↓") -> ↑ | F12: Net loss decreased by 72.5% YoY, primarily driven by the normalization of non-recurring items recognized during FY2023–FY2024 and improved operating performance.
B14: ── CASH & LIQUIDITY ────────────
B15: Cash & Equivalents (Rp Millions) | C15: =BS!E6 -> 19177524 | D15: =BS!F6 -> 21755165 | E15: =IF(D15-C15>0, "↑", "↓") -> ↑ | F15: GoTo maintains a strong liquidity position, providing sufficient financial flexibility to support ongoing operations and strategic investments.
B16: OCF (Rp Millions) | C16: =CF!E60 -> -622114 | D16: =CF!F60 -> 307025 | E16: =IF(D16-C16>0, "↑", "↓") -> ↑ | F16: FY2025 marked the Company's first year of positive operating cash flow, representing an important milestone in its path toward sustainable profitability.
B17: FCF (Rp Millions) | C17: =CF!E62 -> -7140976 | D17: =CF!F62 -> -875335 | E17: =IF(D17-C17>0, "↑", "↓") -> ↑ | F17: Free cash flow remained negative due to continued investment in platform development and long-term growth initiatives, although cash outflows improved substantially year over year.
B18: FCF Margin (%) | C18: =CF!E63 -> -0.44927447 | D18: =CF!F63 -> -0.047774774 | E18: =IF(D18-C18>0, "↑", "↓") -> ↑
B20: ── OPERATIONAL EFFICIENCY ──────
B21: G&A as % of Revenue | C21: =ABS(IS!E8/IS!E4) -> 0.27659024 | D21: =ABS(IS!F8/IS!F4) -> 0.21771092 | E21: =IF(D21-C21>0, "↑", "↓") -> ↓
B22: S&M as % of Revenue | C22: =ABS(IS!E9/IS!E4) -> 0.17930358 | D22: =ABS(IS!F9/IS!F4) -> 0.1686554 | E22: =IF(D22-C22>0, "↑", "↓") -> ↓
B23: Capex as % of Revenue | C23: =(BS!E25+BS!E26)/IS!E4 -> 0.12005848 | D23: =(BS!F25+BS!F26)/IS!F4 -> 0.11938888 | E23: =IF(D23-C23>0, "↑", "↓") -> ↓
B25: ── PER SHARE METRICS ───────────
B26: Loss per Share — Basic (Rp) | C26: =IS!E37 -> -4.8 | D26: =IS!F37 -> -1.1 | E26: =IF(D26-C26>0, "↑", "↓") -> ↑ | F26: Loss pershare mengecil menunjukkan improvement GoTo

Sheet RATIOS
B1: GOTO (GOTO.JK) — Ratio Analysis
B2: All ratios calculated from IS / BS / CF sheets
B3: Ratio | C3: FY2024 | D3: FY2025 | E3: Δ | F3: Interpretation Guide
B4: A. PROFITABILITY RATIOS
B5: Gross Profit Margin | F5: Higher = more efficient cost of delivery
B6: Operating Loss Margin | F6: Narrowing loss = path to profitability
B7: Net Loss Margin | F7: Comprehensive bottom-line efficiency
B8: Adjusted EBITDA Margin | F8: Management KPI — operational cash generation
B9: Return on Assets (ROA) | F9: Loss / Avg Total Assets
B10: Return on Equity (ROE) | F10: Loss / Avg Total Equity
B11: B. LIQUIDITY RATIOS
B12: Current Ratio | F12: >1.0x = current assets cover current liabilities
B13: Quick Ratio | F13: (Current Assets - Inventories) / Current Liabilities
B14: Cash Ratio | F14: Cash / Current Liabilities — most conservative
B15: Cash & Equivalents (Rp Juta) | F15: Absolute cash position
B16: Cash as % of Total Assets | F16: Liquidity concentration — GOTO very high
B17: C. LEVERAGE / SOLVENCY RATIOS
B18: Total Debt (Rp Juta) | F18: ST + LT borrowings, excl. leases
B19: Net Cash / (Net Debt) (Rp Juta) | F19: Positive = net cash company
B20: Debt-to-Equity Ratio | F20: Total Liabilities / Total Equity
B21: Debt-to-Assets Ratio | F21: Total Liabilities / Total Assets
B22: Interest Coverage (EBITDA/Interest) | F22: Ability to service debt — negative EBITDA = n/m
B23: D. EFFICIENCY RATIOS
B24: Asset Turnover | F24: Revenue / Avg Total Assets
B25: Receivables Turnover | F25: Revenue / Avg Trade Receivables
B26: G&A as % of Revenue | F26: Cost discipline — should decline over time
B27: S&M as % of Revenue | F27: Customer acquisition investment
B28: R&D (Product Dev) as % Rev | F28: Innovation investment intensity
B29: Capex as % of Revenue | F29: Capital intensity — tech should be low
B30: E. CASH FLOW RATIOS
B31: OCF Margin | F31: OCF / Revenue — ability to convert revenue to cash
B32: FCF Margin | F32: FCF / Revenue — after capex
B33: Cash Conversion (OCF/EBITDA) | F33: Quality of earnings — how much EBITDA becomes cash
B34: OCF to Total Debt | F34: Debt repayment capacity from operations
B35: F. TECH / PLATFORM-SPECIFIC KPIs
B36: Total GTV (Rp Juta) | F36: Gross transaction value through the platform
B37: Take Rate — Consolidated | F37: Revenue / GTV — monetization efficiency
B38: On-Demand Take Rate
B39: E-commerce Take Rate
B40: Financial Services Take Rate
...
